[2024-10-23T07:13:45.400+0000] {local_task_job_runner.py:123} INFO - ::group::Pre task execution logs
[2024-10-23T07:13:45.416+0000] {taskinstance.py:2612} INFO - Dependencies all met for dep_context=non-requeueable deps ti=<TaskInstance: dcard_dag.run_crawl_task manual__2024-10-23T07:13:35.052810+00:00 [queued]>
[2024-10-23T07:13:45.427+0000] {taskinstance.py:2612} INFO - Dependencies all met for dep_context=requeueable deps ti=<TaskInstance: dcard_dag.run_crawl_task manual__2024-10-23T07:13:35.052810+00:00 [queued]>
[2024-10-23T07:13:45.427+0000] {taskinstance.py:2865} INFO - Starting attempt 1 of 2
[2024-10-23T07:13:45.454+0000] {taskinstance.py:2888} INFO - Executing <Task(PythonOperator): run_crawl_task> on 2024-10-23 07:13:35.052810+00:00
[2024-10-23T07:13:45.460+0000] {standard_task_runner.py:72} INFO - Started process 20859 to run task
[2024-10-23T07:13:45.467+0000] {standard_task_runner.py:104} INFO - Running: ['airflow', 'tasks', 'run', 'dcard_dag', 'run_crawl_task', 'manual__2024-10-23T07:13:35.052810+00:00', '--job-id', '858', '--raw', '--subdir', 'DAGS_FOLDER/dcard_dag.py', '--cfg-path', '/tmp/tmp3kj4dc9j']
[2024-10-23T07:13:45.469+0000] {standard_task_runner.py:105} INFO - Job 858: Subtask run_crawl_task
[2024-10-23T07:13:45.525+0000] {task_command.py:467} INFO - Running <TaskInstance: dcard_dag.run_crawl_task manual__2024-10-23T07:13:35.052810+00:00 [running]> on host 60bbe790d101
[2024-10-23T07:13:45.632+0000] {taskinstance.py:3131} INFO - Exporting env vars: AIRFLOW_CTX_DAG_OWNER='airflow' AIRFLOW_CTX_DAG_ID='dcard_dag' AIRFLOW_CTX_TASK_ID='run_crawl_task' AIRFLOW_CTX_EXECUTION_DATE='2024-10-23T07:13:35.052810+00:00' AIRFLOW_CTX_TRY_NUMBER='1' AIRFLOW_CTX_DAG_RUN_ID='manual__2024-10-23T07:13:35.052810+00:00'
[2024-10-23T07:13:45.633+0000] {taskinstance.py:731} INFO - ::endgroup::
[2024-10-23T07:13:45.700+0000] {logger.py:11} INFO - ====== WebDriver manager ======
[2024-10-23T07:13:46.300+0000] {logger.py:11} INFO - Get LATEST chromedriver version for google-chrome
[2024-10-23T07:13:46.439+0000] {logger.py:11} INFO - Get LATEST chromedriver version for google-chrome
[2024-10-23T07:13:46.571+0000] {logger.py:11} INFO - Driver [/home/airflow/.wdm/drivers/chromedriver/linux64/130.0.6723.69/chromedriver-linux64/chromedriver] found in cache
[2024-10-23T07:13:58.957+0000] {taskinstance.py:3310} ERROR - Task failed with exception
Traceback (most recent call last):
  File "/opt/airflow/dags/dcard_dag.py", line 62, in crawl_dcard
    element_by_data_key = driver.find_element(By.XPATH, f"//div[@data-key='{i}']")
                          ^^^^^^^^^^^^^^^^^^^^^^^^^^^^^^^^^^^^^^^^^^^^^^^^^^^^^^^^
  File "/home/airflow/.local/lib/python3.12/site-packages/selenium/webdriver/remote/webdriver.py", line 748, in find_element
    return self.execute(Command.FIND_ELEMENT, {"using": by, "value": value})["value"]
           ^^^^^^^^^^^^^^^^^^^^^^^^^^^^^^^^^^^^^^^^^^^^^^^^^^^^^^^^^^^^^^^^^
  File "/home/airflow/.local/lib/python3.12/site-packages/selenium/webdriver/remote/webdriver.py", line 354, in execute
    self.error_handler.check_response(response)
  File "/home/airflow/.local/lib/python3.12/site-packages/selenium/webdriver/remote/errorhandler.py", line 229, in check_response
    raise exception_class(message, screen, stacktrace)
selenium.common.exceptions.NoSuchElementException: Message: no such element: Unable to locate element: {"method":"xpath","selector":"//div[@data-key='1']"}
  (Session info: chrome=130.0.6723.58); For documentation on this error, please visit: https://www.selenium.dev/documentation/webdriver/troubleshooting/errors#no-such-element-exception
Stacktrace:
#0 0x55c6c2c0710a <unknown>
#1 0x55c6c2722460 <unknown>
#2 0x55c6c276ef96 <unknown>
#3 0x55c6c276f221 <unknown>
#4 0x55c6c27b45d4 <unknown>
#5 0x55c6c279303d <unknown>
#6 0x55c6c27b1af6 <unknown>
#7 0x55c6c2792db3 <unknown>
#8 0x55c6c2761c10 <unknown>
#9 0x55c6c2762bee <unknown>
#10 0x55c6c2bd339b <unknown>
#11 0x55c6c2bd7338 <unknown>
#12 0x55c6c2bc0ebc <unknown>
#13 0x55c6c2bd7eb7 <unknown>
#14 0x55c6c2ba610f <unknown>
#15 0x55c6c2bf5828 <unknown>
#16 0x55c6c2bf59f0 <unknown>
#17 0x55c6c2c05f86 <unknown>
#18 0x7fc4818de144 <unknown>


During handling of the above exception, another exception occurred:

Traceback (most recent call last):
  File "/home/airflow/.local/lib/python3.12/site-packages/airflow/models/taskinstance.py", line 767, in _execute_task
    result = _execute_callable(context=context, **execute_callable_kwargs)
             ^^^^^^^^^^^^^^^^^^^^^^^^^^^^^^^^^^^^^^^^^^^^^^^^^^^^^^^^^^^^^
  File "/home/airflow/.local/lib/python3.12/site-packages/airflow/models/taskinstance.py", line 733, in _execute_callable
    return ExecutionCallableRunner(
           ^^^^^^^^^^^^^^^^^^^^^^^^
  File "/home/airflow/.local/lib/python3.12/site-packages/airflow/utils/operator_helpers.py", line 252, in run
    return self.func(*args, **kwargs)
           ^^^^^^^^^^^^^^^^^^^^^^^^^^
  File "/home/airflow/.local/lib/python3.12/site-packages/airflow/models/baseoperator.py", line 406, in wrapper
    return func(self, *args, **kwargs)
           ^^^^^^^^^^^^^^^^^^^^^^^^^^^
  File "/home/airflow/.local/lib/python3.12/site-packages/airflow/operators/python.py", line 238, in execute
    return_value = self.execute_callable()
                   ^^^^^^^^^^^^^^^^^^^^^^^
  File "/home/airflow/.local/lib/python3.12/site-packages/airflow/operators/python.py", line 256, in execute_callable
    return runner.run(*self.op_args, **self.op_kwargs)
           ^^^^^^^^^^^^^^^^^^^^^^^^^^^^^^^^^^^^^^^^^^^
  File "/home/airflow/.local/lib/python3.12/site-packages/airflow/utils/operator_helpers.py", line 252, in run
    return self.func(*args, **kwargs)
           ^^^^^^^^^^^^^^^^^^^^^^^^^^
  File "/opt/airflow/dags/dcard_dag.py", line 222, in crawl_dcard
    driver1.quit()
    ^^^^^^^
UnboundLocalError: cannot access local variable 'driver1' where it is not associated with a value
[2024-10-23T07:13:59.025+0000] {taskinstance.py:1225} INFO - Marking task as UP_FOR_RETRY. dag_id=dcard_dag, task_id=run_crawl_task, run_id=manual__2024-10-23T07:13:35.052810+00:00, execution_date=20241023T071335, start_date=20241023T071345, end_date=20241023T071359
[2024-10-23T07:13:59.074+0000] {taskinstance.py:340} INFO - ::group::Post task execution logs
[2024-10-23T07:13:59.075+0000] {standard_task_runner.py:124} ERROR - Failed to execute job 858 for task run_crawl_task (cannot access local variable 'driver1' where it is not associated with a value; 20859)
Traceback (most recent call last):
  File "/opt/airflow/dags/dcard_dag.py", line 62, in crawl_dcard
    element_by_data_key = driver.find_element(By.XPATH, f"//div[@data-key='{i}']")
                          ^^^^^^^^^^^^^^^^^^^^^^^^^^^^^^^^^^^^^^^^^^^^^^^^^^^^^^^^
  File "/home/airflow/.local/lib/python3.12/site-packages/selenium/webdriver/remote/webdriver.py", line 748, in find_element
    return self.execute(Command.FIND_ELEMENT, {"using": by, "value": value})["value"]
           ^^^^^^^^^^^^^^^^^^^^^^^^^^^^^^^^^^^^^^^^^^^^^^^^^^^^^^^^^^^^^^^^^
  File "/home/airflow/.local/lib/python3.12/site-packages/selenium/webdriver/remote/webdriver.py", line 354, in execute
    self.error_handler.check_response(response)
  File "/home/airflow/.local/lib/python3.12/site-packages/selenium/webdriver/remote/errorhandler.py", line 229, in check_response
    raise exception_class(message, screen, stacktrace)
selenium.common.exceptions.NoSuchElementException: Message: no such element: Unable to locate element: {"method":"xpath","selector":"//div[@data-key='1']"}
  (Session info: chrome=130.0.6723.58); For documentation on this error, please visit: https://www.selenium.dev/documentation/webdriver/troubleshooting/errors#no-such-element-exception
Stacktrace:
#0 0x55c6c2c0710a <unknown>
#1 0x55c6c2722460 <unknown>
#2 0x55c6c276ef96 <unknown>
#3 0x55c6c276f221 <unknown>
#4 0x55c6c27b45d4 <unknown>
#5 0x55c6c279303d <unknown>
#6 0x55c6c27b1af6 <unknown>
#7 0x55c6c2792db3 <unknown>
#8 0x55c6c2761c10 <unknown>
#9 0x55c6c2762bee <unknown>
#10 0x55c6c2bd339b <unknown>
#11 0x55c6c2bd7338 <unknown>
#12 0x55c6c2bc0ebc <unknown>
#13 0x55c6c2bd7eb7 <unknown>
#14 0x55c6c2ba610f <unknown>
#15 0x55c6c2bf5828 <unknown>
#16 0x55c6c2bf59f0 <unknown>
#17 0x55c6c2c05f86 <unknown>
#18 0x7fc4818de144 <unknown>


During handling of the above exception, another exception occurred:

Traceback (most recent call last):
  File "/home/airflow/.local/lib/python3.12/site-packages/airflow/task/task_runner/standard_task_runner.py", line 117, in _start_by_fork
    ret = args.func(args, dag=self.dag)
          ^^^^^^^^^^^^^^^^^^^^^^^^^^^^^
  File "/home/airflow/.local/lib/python3.12/site-packages/airflow/cli/cli_config.py", line 49, in command
    return func(*args, **kwargs)
           ^^^^^^^^^^^^^^^^^^^^^
  File "/home/airflow/.local/lib/python3.12/site-packages/airflow/utils/cli.py", line 115, in wrapper
    return f(*args, **kwargs)
           ^^^^^^^^^^^^^^^^^^
  File "/home/airflow/.local/lib/python3.12/site-packages/airflow/cli/commands/task_command.py", line 483, in task_run
    task_return_code = _run_task_by_selected_method(args, _dag, ti)
                       ^^^^^^^^^^^^^^^^^^^^^^^^^^^^^^^^^^^^^^^^^^^^
  File "/home/airflow/.local/lib/python3.12/site-packages/airflow/cli/commands/task_command.py", line 256, in _run_task_by_selected_method
    return _run_raw_task(args, ti)
           ^^^^^^^^^^^^^^^^^^^^^^^
  File "/home/airflow/.local/lib/python3.12/site-packages/airflow/cli/commands/task_command.py", line 341, in _run_raw_task
    return ti._run_raw_task(
           ^^^^^^^^^^^^^^^^^
  File "/home/airflow/.local/lib/python3.12/site-packages/airflow/utils/session.py", line 97, in wrapper
    return func(*args, session=session, **kwargs)
           ^^^^^^^^^^^^^^^^^^^^^^^^^^^^^^^^^^^^^^
  File "/home/airflow/.local/lib/python3.12/site-packages/airflow/models/taskinstance.py", line 3004, in _run_raw_task
    return _run_raw_task(
           ^^^^^^^^^^^^^^
  File "/home/airflow/.local/lib/python3.12/site-packages/airflow/models/taskinstance.py", line 273, in _run_raw_task
    TaskInstance._execute_task_with_callbacks(
  File "/home/airflow/.local/lib/python3.12/site-packages/airflow/models/taskinstance.py", line 3158, in _execute_task_with_callbacks
    result = self._execute_task(context, task_orig)
             ^^^^^^^^^^^^^^^^^^^^^^^^^^^^^^^^^^^^^^
  File "/home/airflow/.local/lib/python3.12/site-packages/airflow/models/taskinstance.py", line 3182, in _execute_task
    return _execute_task(self, context, task_orig)
           ^^^^^^^^^^^^^^^^^^^^^^^^^^^^^^^^^^^^^^^
  File "/home/airflow/.local/lib/python3.12/site-packages/airflow/models/taskinstance.py", line 767, in _execute_task
    result = _execute_callable(context=context, **execute_callable_kwargs)
             ^^^^^^^^^^^^^^^^^^^^^^^^^^^^^^^^^^^^^^^^^^^^^^^^^^^^^^^^^^^^^
  File "/home/airflow/.local/lib/python3.12/site-packages/airflow/models/taskinstance.py", line 733, in _execute_callable
    return ExecutionCallableRunner(
           ^^^^^^^^^^^^^^^^^^^^^^^^
  File "/home/airflow/.local/lib/python3.12/site-packages/airflow/utils/operator_helpers.py", line 252, in run
    return self.func(*args, **kwargs)
           ^^^^^^^^^^^^^^^^^^^^^^^^^^
  File "/home/airflow/.local/lib/python3.12/site-packages/airflow/models/baseoperator.py", line 406, in wrapper
    return func(self, *args, **kwargs)
           ^^^^^^^^^^^^^^^^^^^^^^^^^^^
  File "/home/airflow/.local/lib/python3.12/site-packages/airflow/operators/python.py", line 238, in execute
    return_value = self.execute_callable()
                   ^^^^^^^^^^^^^^^^^^^^^^^
  File "/home/airflow/.local/lib/python3.12/site-packages/airflow/operators/python.py", line 256, in execute_callable
    return runner.run(*self.op_args, **self.op_kwargs)
           ^^^^^^^^^^^^^^^^^^^^^^^^^^^^^^^^^^^^^^^^^^^
  File "/home/airflow/.local/lib/python3.12/site-packages/airflow/utils/operator_helpers.py", line 252, in run
    return self.func(*args, **kwargs)
           ^^^^^^^^^^^^^^^^^^^^^^^^^^
  File "/opt/airflow/dags/dcard_dag.py", line 222, in crawl_dcard
    driver1.quit()
    ^^^^^^^
UnboundLocalError: cannot access local variable 'driver1' where it is not associated with a value
[2024-10-23T07:13:59.151+0000] {local_task_job_runner.py:266} INFO - Task exited with return code 1
[2024-10-23T07:13:59.175+0000] {taskinstance.py:3900} INFO - 0 downstream tasks scheduled from follow-on schedule check
[2024-10-23T07:13:59.176+0000] {local_task_job_runner.py:245} INFO - ::endgroup::
