[2024-10-24T08:38:22.992+0000] {local_task_job_runner.py:123} INFO - ::group::Pre task execution logs
[2024-10-24T08:38:23.004+0000] {taskinstance.py:2612} INFO - Dependencies all met for dep_context=non-requeueable deps ti=<TaskInstance: test3.run_selenium_task manual__2024-10-24T08:38:17.337522+00:00 [queued]>
[2024-10-24T08:38:23.011+0000] {taskinstance.py:2612} INFO - Dependencies all met for dep_context=requeueable deps ti=<TaskInstance: test3.run_selenium_task manual__2024-10-24T08:38:17.337522+00:00 [queued]>
[2024-10-24T08:38:23.012+0000] {taskinstance.py:2865} INFO - Starting attempt 1 of 2
[2024-10-24T08:38:23.030+0000] {taskinstance.py:2888} INFO - Executing <Task(PythonOperator): run_selenium_task> on 2024-10-24 08:38:17.337522+00:00
[2024-10-24T08:38:23.036+0000] {standard_task_runner.py:72} INFO - Started process 5566 to run task
[2024-10-24T08:38:23.041+0000] {standard_task_runner.py:104} INFO - Running: ['airflow', 'tasks', 'run', 'test3', 'run_selenium_task', 'manual__2024-10-24T08:38:17.337522+00:00', '--job-id', '892', '--raw', '--subdir', 'DAGS_FOLDER/dcard_dag.py', '--cfg-path', '/tmp/tmp_tui041s']
[2024-10-24T08:38:23.043+0000] {standard_task_runner.py:105} INFO - Job 892: Subtask run_selenium_task
[2024-10-24T08:38:23.090+0000] {task_command.py:467} INFO - Running <TaskInstance: test3.run_selenium_task manual__2024-10-24T08:38:17.337522+00:00 [running]> on host 60bbe790d101
[2024-10-24T08:38:23.175+0000] {taskinstance.py:3131} INFO - Exporting env vars: AIRFLOW_CTX_DAG_OWNER='airflow' AIRFLOW_CTX_DAG_ID='test3' AIRFLOW_CTX_TASK_ID='run_selenium_task' AIRFLOW_CTX_EXECUTION_DATE='2024-10-24T08:38:17.337522+00:00' AIRFLOW_CTX_TRY_NUMBER='1' AIRFLOW_CTX_DAG_RUN_ID='manual__2024-10-24T08:38:17.337522+00:00'
[2024-10-24T08:38:23.176+0000] {taskinstance.py:731} INFO - ::endgroup::
[2024-10-24T08:38:23.200+0000] {logger.py:11} INFO - ====== WebDriver manager ======
[2024-10-24T08:38:23.317+0000] {logger.py:11} INFO - Get LATEST chromedriver version for google-chrome
[2024-10-24T08:38:23.451+0000] {logger.py:11} INFO - Get LATEST chromedriver version for google-chrome
[2024-10-24T08:38:23.586+0000] {logger.py:11} INFO - Driver [/home/airflow/.wdm/drivers/chromedriver/linux64/130.0.6723.69/chromedriver] found in cache
[2024-10-24T08:38:45.301+0000] {logging_mixin.py:190} INFO - Attention Required! | Cloudflare
[2024-10-24T08:38:45.327+0000] {taskinstance.py:3310} ERROR - Task failed with exception
Traceback (most recent call last):
  File "/opt/airflow/dags/dcard_dag.py", line 71, in selenium_scraper
    element_by_data_key = driver.find_element(By.XPATH, f"//div[@data-key='{i}']")
                          ^^^^^^^^^^^^^^^^^^^^^^^^^^^^^^^^^^^^^^^^^^^^^^^^^^^^^^^^
  File "/home/airflow/.local/lib/python3.12/site-packages/selenium/webdriver/remote/webdriver.py", line 748, in find_element
    return self.execute(Command.FIND_ELEMENT, {"using": by, "value": value})["value"]
           ^^^^^^^^^^^^^^^^^^^^^^^^^^^^^^^^^^^^^^^^^^^^^^^^^^^^^^^^^^^^^^^^^
  File "/home/airflow/.local/lib/python3.12/site-packages/selenium/webdriver/remote/webdriver.py", line 354, in execute
    self.error_handler.check_response(response)
  File "/home/airflow/.local/lib/python3.12/site-packages/selenium/webdriver/remote/errorhandler.py", line 229, in check_response
    raise exception_class(message, screen, stacktrace)
selenium.common.exceptions.NoSuchElementException: Message: no such element: Unable to locate element: {"method":"xpath","selector":"//div[@data-key='1']"}
  (Session info: chrome=130.0.6723.58); For documentation on this error, please visit: https://www.selenium.dev/documentation/webdriver/troubleshooting/errors#no-such-element-exception
Stacktrace:
#0 0x558c7d9e110a <unknown>
#1 0x558c7d4fc460 <unknown>
#2 0x558c7d548f96 <unknown>
#3 0x558c7d549221 <unknown>
#4 0x558c7d58e5d4 <unknown>
#5 0x558c7d56d03d <unknown>
#6 0x558c7d58baf6 <unknown>
#7 0x558c7d56cdb3 <unknown>
#8 0x558c7d53bc10 <unknown>
#9 0x558c7d53cbee <unknown>
#10 0x558c7d9ad39b <unknown>
#11 0x558c7d9b1338 <unknown>
#12 0x558c7d99aebc <unknown>
#13 0x558c7d9b1eb7 <unknown>
#14 0x558c7d98010f <unknown>
#15 0x558c7d9cf828 <unknown>
#16 0x558c7d9cf9f0 <unknown>
#17 0x558c7d9dff86 <unknown>
#18 0x7f0313674144 <unknown>


During handling of the above exception, another exception occurred:

Traceback (most recent call last):
  File "/home/airflow/.local/lib/python3.12/site-packages/airflow/models/taskinstance.py", line 767, in _execute_task
    result = _execute_callable(context=context, **execute_callable_kwargs)
             ^^^^^^^^^^^^^^^^^^^^^^^^^^^^^^^^^^^^^^^^^^^^^^^^^^^^^^^^^^^^^
  File "/home/airflow/.local/lib/python3.12/site-packages/airflow/models/taskinstance.py", line 733, in _execute_callable
    return ExecutionCallableRunner(
           ^^^^^^^^^^^^^^^^^^^^^^^^
  File "/home/airflow/.local/lib/python3.12/site-packages/airflow/utils/operator_helpers.py", line 252, in run
    return self.func(*args, **kwargs)
           ^^^^^^^^^^^^^^^^^^^^^^^^^^
  File "/home/airflow/.local/lib/python3.12/site-packages/airflow/models/baseoperator.py", line 406, in wrapper
    return func(self, *args, **kwargs)
           ^^^^^^^^^^^^^^^^^^^^^^^^^^^
  File "/home/airflow/.local/lib/python3.12/site-packages/airflow/operators/python.py", line 238, in execute
    return_value = self.execute_callable()
                   ^^^^^^^^^^^^^^^^^^^^^^^
  File "/home/airflow/.local/lib/python3.12/site-packages/airflow/operators/python.py", line 256, in execute_callable
    return runner.run(*self.op_args, **self.op_kwargs)
           ^^^^^^^^^^^^^^^^^^^^^^^^^^^^^^^^^^^^^^^^^^^
  File "/home/airflow/.local/lib/python3.12/site-packages/airflow/utils/operator_helpers.py", line 252, in run
    return self.func(*args, **kwargs)
           ^^^^^^^^^^^^^^^^^^^^^^^^^^
  File "/opt/airflow/dags/dcard_dag.py", line 218, in selenium_scraper
    driver1.quit()
    ^^^^^^^
UnboundLocalError: cannot access local variable 'driver1' where it is not associated with a value
[2024-10-24T08:38:45.338+0000] {taskinstance.py:1225} INFO - Marking task as UP_FOR_RETRY. dag_id=test3, task_id=run_selenium_task, run_id=manual__2024-10-24T08:38:17.337522+00:00, execution_date=20241024T083817, start_date=20241024T083823, end_date=20241024T083845
[2024-10-24T08:38:45.354+0000] {taskinstance.py:340} INFO - ::group::Post task execution logs
[2024-10-24T08:38:45.354+0000] {standard_task_runner.py:124} ERROR - Failed to execute job 892 for task run_selenium_task (cannot access local variable 'driver1' where it is not associated with a value; 5566)
Traceback (most recent call last):
  File "/opt/airflow/dags/dcard_dag.py", line 71, in selenium_scraper
    element_by_data_key = driver.find_element(By.XPATH, f"//div[@data-key='{i}']")
                          ^^^^^^^^^^^^^^^^^^^^^^^^^^^^^^^^^^^^^^^^^^^^^^^^^^^^^^^^
  File "/home/airflow/.local/lib/python3.12/site-packages/selenium/webdriver/remote/webdriver.py", line 748, in find_element
    return self.execute(Command.FIND_ELEMENT, {"using": by, "value": value})["value"]
           ^^^^^^^^^^^^^^^^^^^^^^^^^^^^^^^^^^^^^^^^^^^^^^^^^^^^^^^^^^^^^^^^^
  File "/home/airflow/.local/lib/python3.12/site-packages/selenium/webdriver/remote/webdriver.py", line 354, in execute
    self.error_handler.check_response(response)
  File "/home/airflow/.local/lib/python3.12/site-packages/selenium/webdriver/remote/errorhandler.py", line 229, in check_response
    raise exception_class(message, screen, stacktrace)
selenium.common.exceptions.NoSuchElementException: Message: no such element: Unable to locate element: {"method":"xpath","selector":"//div[@data-key='1']"}
  (Session info: chrome=130.0.6723.58); For documentation on this error, please visit: https://www.selenium.dev/documentation/webdriver/troubleshooting/errors#no-such-element-exception
Stacktrace:
#0 0x558c7d9e110a <unknown>
#1 0x558c7d4fc460 <unknown>
#2 0x558c7d548f96 <unknown>
#3 0x558c7d549221 <unknown>
#4 0x558c7d58e5d4 <unknown>
#5 0x558c7d56d03d <unknown>
#6 0x558c7d58baf6 <unknown>
#7 0x558c7d56cdb3 <unknown>
#8 0x558c7d53bc10 <unknown>
#9 0x558c7d53cbee <unknown>
#10 0x558c7d9ad39b <unknown>
#11 0x558c7d9b1338 <unknown>
#12 0x558c7d99aebc <unknown>
#13 0x558c7d9b1eb7 <unknown>
#14 0x558c7d98010f <unknown>
#15 0x558c7d9cf828 <unknown>
#16 0x558c7d9cf9f0 <unknown>
#17 0x558c7d9dff86 <unknown>
#18 0x7f0313674144 <unknown>


During handling of the above exception, another exception occurred:

Traceback (most recent call last):
  File "/home/airflow/.local/lib/python3.12/site-packages/airflow/task/task_runner/standard_task_runner.py", line 117, in _start_by_fork
    ret = args.func(args, dag=self.dag)
          ^^^^^^^^^^^^^^^^^^^^^^^^^^^^^
  File "/home/airflow/.local/lib/python3.12/site-packages/airflow/cli/cli_config.py", line 49, in command
    return func(*args, **kwargs)
           ^^^^^^^^^^^^^^^^^^^^^
  File "/home/airflow/.local/lib/python3.12/site-packages/airflow/utils/cli.py", line 115, in wrapper
    return f(*args, **kwargs)
           ^^^^^^^^^^^^^^^^^^
  File "/home/airflow/.local/lib/python3.12/site-packages/airflow/cli/commands/task_command.py", line 483, in task_run
    task_return_code = _run_task_by_selected_method(args, _dag, ti)
                       ^^^^^^^^^^^^^^^^^^^^^^^^^^^^^^^^^^^^^^^^^^^^
  File "/home/airflow/.local/lib/python3.12/site-packages/airflow/cli/commands/task_command.py", line 256, in _run_task_by_selected_method
    return _run_raw_task(args, ti)
           ^^^^^^^^^^^^^^^^^^^^^^^
  File "/home/airflow/.local/lib/python3.12/site-packages/airflow/cli/commands/task_command.py", line 341, in _run_raw_task
    return ti._run_raw_task(
           ^^^^^^^^^^^^^^^^^
  File "/home/airflow/.local/lib/python3.12/site-packages/airflow/utils/session.py", line 97, in wrapper
    return func(*args, session=session, **kwargs)
           ^^^^^^^^^^^^^^^^^^^^^^^^^^^^^^^^^^^^^^
  File "/home/airflow/.local/lib/python3.12/site-packages/airflow/models/taskinstance.py", line 3004, in _run_raw_task
    return _run_raw_task(
           ^^^^^^^^^^^^^^
  File "/home/airflow/.local/lib/python3.12/site-packages/airflow/models/taskinstance.py", line 273, in _run_raw_task
    TaskInstance._execute_task_with_callbacks(
  File "/home/airflow/.local/lib/python3.12/site-packages/airflow/models/taskinstance.py", line 3158, in _execute_task_with_callbacks
    result = self._execute_task(context, task_orig)
             ^^^^^^^^^^^^^^^^^^^^^^^^^^^^^^^^^^^^^^
  File "/home/airflow/.local/lib/python3.12/site-packages/airflow/models/taskinstance.py", line 3182, in _execute_task
    return _execute_task(self, context, task_orig)
           ^^^^^^^^^^^^^^^^^^^^^^^^^^^^^^^^^^^^^^^
  File "/home/airflow/.local/lib/python3.12/site-packages/airflow/models/taskinstance.py", line 767, in _execute_task
    result = _execute_callable(context=context, **execute_callable_kwargs)
             ^^^^^^^^^^^^^^^^^^^^^^^^^^^^^^^^^^^^^^^^^^^^^^^^^^^^^^^^^^^^^
  File "/home/airflow/.local/lib/python3.12/site-packages/airflow/models/taskinstance.py", line 733, in _execute_callable
    return ExecutionCallableRunner(
           ^^^^^^^^^^^^^^^^^^^^^^^^
  File "/home/airflow/.local/lib/python3.12/site-packages/airflow/utils/operator_helpers.py", line 252, in run
    return self.func(*args, **kwargs)
           ^^^^^^^^^^^^^^^^^^^^^^^^^^
  File "/home/airflow/.local/lib/python3.12/site-packages/airflow/models/baseoperator.py", line 406, in wrapper
    return func(self, *args, **kwargs)
           ^^^^^^^^^^^^^^^^^^^^^^^^^^^
  File "/home/airflow/.local/lib/python3.12/site-packages/airflow/operators/python.py", line 238, in execute
    return_value = self.execute_callable()
                   ^^^^^^^^^^^^^^^^^^^^^^^
  File "/home/airflow/.local/lib/python3.12/site-packages/airflow/operators/python.py", line 256, in execute_callable
    return runner.run(*self.op_args, **self.op_kwargs)
           ^^^^^^^^^^^^^^^^^^^^^^^^^^^^^^^^^^^^^^^^^^^
  File "/home/airflow/.local/lib/python3.12/site-packages/airflow/utils/operator_helpers.py", line 252, in run
    return self.func(*args, **kwargs)
           ^^^^^^^^^^^^^^^^^^^^^^^^^^
  File "/opt/airflow/dags/dcard_dag.py", line 218, in selenium_scraper
    driver1.quit()
    ^^^^^^^
UnboundLocalError: cannot access local variable 'driver1' where it is not associated with a value
[2024-10-24T08:38:45.406+0000] {local_task_job_runner.py:266} INFO - Task exited with return code 1
[2024-10-24T08:38:45.418+0000] {taskinstance.py:3900} INFO - 0 downstream tasks scheduled from follow-on schedule check
[2024-10-24T08:38:45.419+0000] {local_task_job_runner.py:245} INFO - ::endgroup::
