[2024-10-23T07:15:25.993+0000] {local_task_job_runner.py:123} INFO - ::group::Pre task execution logs
[2024-10-23T07:15:26.014+0000] {taskinstance.py:2612} INFO - Dependencies all met for dep_context=non-requeueable deps ti=<TaskInstance: dcard_dag.run_crawl_task manual__2024-10-23T07:15:15.166122+00:00 [queued]>
[2024-10-23T07:15:26.024+0000] {taskinstance.py:2612} INFO - Dependencies all met for dep_context=requeueable deps ti=<TaskInstance: dcard_dag.run_crawl_task manual__2024-10-23T07:15:15.166122+00:00 [queued]>
[2024-10-23T07:15:26.024+0000] {taskinstance.py:2865} INFO - Starting attempt 1 of 2
[2024-10-23T07:15:26.057+0000] {taskinstance.py:2888} INFO - Executing <Task(PythonOperator): run_crawl_task> on 2024-10-23 07:15:15.166122+00:00
[2024-10-23T07:15:26.064+0000] {standard_task_runner.py:72} INFO - Started process 21138 to run task
[2024-10-23T07:15:26.071+0000] {standard_task_runner.py:104} INFO - Running: ['airflow', 'tasks', 'run', 'dcard_dag', 'run_crawl_task', 'manual__2024-10-23T07:15:15.166122+00:00', '--job-id', '855', '--raw', '--subdir', 'DAGS_FOLDER/dcard_dag.py', '--cfg-path', '/tmp/tmp_hkyy2we']
[2024-10-23T07:15:26.074+0000] {standard_task_runner.py:105} INFO - Job 855: Subtask run_crawl_task
[2024-10-23T07:15:26.140+0000] {task_command.py:467} INFO - Running <TaskInstance: dcard_dag.run_crawl_task manual__2024-10-23T07:15:15.166122+00:00 [running]> on host 60bbe790d101
[2024-10-23T07:15:26.251+0000] {taskinstance.py:3131} INFO - Exporting env vars: AIRFLOW_CTX_DAG_OWNER='airflow' AIRFLOW_CTX_DAG_ID='dcard_dag' AIRFLOW_CTX_TASK_ID='run_crawl_task' AIRFLOW_CTX_EXECUTION_DATE='2024-10-23T07:15:15.166122+00:00' AIRFLOW_CTX_TRY_NUMBER='1' AIRFLOW_CTX_DAG_RUN_ID='manual__2024-10-23T07:15:15.166122+00:00'
[2024-10-23T07:15:26.252+0000] {taskinstance.py:731} INFO - ::endgroup::
[2024-10-23T07:15:26.335+0000] {logger.py:11} INFO - ====== WebDriver manager ======
[2024-10-23T07:15:26.913+0000] {logger.py:11} INFO - Get LATEST chromedriver version for google-chrome
[2024-10-23T07:15:27.063+0000] {logger.py:11} INFO - Get LATEST chromedriver version for google-chrome
[2024-10-23T07:15:27.201+0000] {logger.py:11} INFO - Driver [/home/airflow/.wdm/drivers/chromedriver/linux64/130.0.6723.69/chromedriver-linux64/chromedriver] found in cache
[2024-10-23T07:15:40.788+0000] {taskinstance.py:3310} ERROR - Task failed with exception
Traceback (most recent call last):
  File "/opt/airflow/dags/dcard_dag.py", line 62, in crawl_dcard
    element_by_data_key = driver.find_element(By.XPATH, f"//div[@data-key='{i}']")
                          ^^^^^^^^^^^^^^^^^^^^^^^^^^^^^^^^^^^^^^^^^^^^^^^^^^^^^^^^
  File "/home/airflow/.local/lib/python3.12/site-packages/selenium/webdriver/remote/webdriver.py", line 748, in find_element
    return self.execute(Command.FIND_ELEMENT, {"using": by, "value": value})["value"]
           ^^^^^^^^^^^^^^^^^^^^^^^^^^^^^^^^^^^^^^^^^^^^^^^^^^^^^^^^^^^^^^^^^
  File "/home/airflow/.local/lib/python3.12/site-packages/selenium/webdriver/remote/webdriver.py", line 354, in execute
    self.error_handler.check_response(response)
  File "/home/airflow/.local/lib/python3.12/site-packages/selenium/webdriver/remote/errorhandler.py", line 229, in check_response
    raise exception_class(message, screen, stacktrace)
selenium.common.exceptions.NoSuchElementException: Message: no such element: Unable to locate element: {"method":"xpath","selector":"//div[@data-key='1']"}
  (Session info: chrome=130.0.6723.58); For documentation on this error, please visit: https://www.selenium.dev/documentation/webdriver/troubleshooting/errors#no-such-element-exception
Stacktrace:
#0 0x561d675e010a <unknown>
#1 0x561d670fb460 <unknown>
#2 0x561d67147f96 <unknown>
#3 0x561d67148221 <unknown>
#4 0x561d6718d5d4 <unknown>
#5 0x561d6716c03d <unknown>
#6 0x561d6718aaf6 <unknown>
#7 0x561d6716bdb3 <unknown>
#8 0x561d6713ac10 <unknown>
#9 0x561d6713bbee <unknown>
#10 0x561d675ac39b <unknown>
#11 0x561d675b0338 <unknown>
#12 0x561d67599ebc <unknown>
#13 0x561d675b0eb7 <unknown>
#14 0x561d6757f10f <unknown>
#15 0x561d675ce828 <unknown>
#16 0x561d675ce9f0 <unknown>
#17 0x561d675def86 <unknown>
#18 0x7fc2fe499144 <unknown>


During handling of the above exception, another exception occurred:

Traceback (most recent call last):
  File "/home/airflow/.local/lib/python3.12/site-packages/airflow/models/taskinstance.py", line 767, in _execute_task
    result = _execute_callable(context=context, **execute_callable_kwargs)
             ^^^^^^^^^^^^^^^^^^^^^^^^^^^^^^^^^^^^^^^^^^^^^^^^^^^^^^^^^^^^^
  File "/home/airflow/.local/lib/python3.12/site-packages/airflow/models/taskinstance.py", line 733, in _execute_callable
    return ExecutionCallableRunner(
           ^^^^^^^^^^^^^^^^^^^^^^^^
  File "/home/airflow/.local/lib/python3.12/site-packages/airflow/utils/operator_helpers.py", line 252, in run
    return self.func(*args, **kwargs)
           ^^^^^^^^^^^^^^^^^^^^^^^^^^
  File "/home/airflow/.local/lib/python3.12/site-packages/airflow/models/baseoperator.py", line 406, in wrapper
    return func(self, *args, **kwargs)
           ^^^^^^^^^^^^^^^^^^^^^^^^^^^
  File "/home/airflow/.local/lib/python3.12/site-packages/airflow/operators/python.py", line 238, in execute
    return_value = self.execute_callable()
                   ^^^^^^^^^^^^^^^^^^^^^^^
  File "/home/airflow/.local/lib/python3.12/site-packages/airflow/operators/python.py", line 256, in execute_callable
    return runner.run(*self.op_args, **self.op_kwargs)
           ^^^^^^^^^^^^^^^^^^^^^^^^^^^^^^^^^^^^^^^^^^^
  File "/home/airflow/.local/lib/python3.12/site-packages/airflow/utils/operator_helpers.py", line 252, in run
    return self.func(*args, **kwargs)
           ^^^^^^^^^^^^^^^^^^^^^^^^^^
  File "/opt/airflow/dags/dcard_dag.py", line 222, in crawl_dcard
    driver1.quit()
    ^^^^^^^
UnboundLocalError: cannot access local variable 'driver1' where it is not associated with a value
[2024-10-23T07:15:40.846+0000] {taskinstance.py:1225} INFO - Marking task as UP_FOR_RETRY. dag_id=dcard_dag, task_id=run_crawl_task, run_id=manual__2024-10-23T07:15:15.166122+00:00, execution_date=20241023T071515, start_date=20241023T071526, end_date=20241023T071540
[2024-10-23T07:15:40.914+0000] {taskinstance.py:340} INFO - ::group::Post task execution logs
[2024-10-23T07:15:40.915+0000] {standard_task_runner.py:124} ERROR - Failed to execute job 855 for task run_crawl_task (cannot access local variable 'driver1' where it is not associated with a value; 21138)
Traceback (most recent call last):
  File "/opt/airflow/dags/dcard_dag.py", line 62, in crawl_dcard
    element_by_data_key = driver.find_element(By.XPATH, f"//div[@data-key='{i}']")
                          ^^^^^^^^^^^^^^^^^^^^^^^^^^^^^^^^^^^^^^^^^^^^^^^^^^^^^^^^
  File "/home/airflow/.local/lib/python3.12/site-packages/selenium/webdriver/remote/webdriver.py", line 748, in find_element
    return self.execute(Command.FIND_ELEMENT, {"using": by, "value": value})["value"]
           ^^^^^^^^^^^^^^^^^^^^^^^^^^^^^^^^^^^^^^^^^^^^^^^^^^^^^^^^^^^^^^^^^
  File "/home/airflow/.local/lib/python3.12/site-packages/selenium/webdriver/remote/webdriver.py", line 354, in execute
    self.error_handler.check_response(response)
  File "/home/airflow/.local/lib/python3.12/site-packages/selenium/webdriver/remote/errorhandler.py", line 229, in check_response
    raise exception_class(message, screen, stacktrace)
selenium.common.exceptions.NoSuchElementException: Message: no such element: Unable to locate element: {"method":"xpath","selector":"//div[@data-key='1']"}
  (Session info: chrome=130.0.6723.58); For documentation on this error, please visit: https://www.selenium.dev/documentation/webdriver/troubleshooting/errors#no-such-element-exception
Stacktrace:
#0 0x561d675e010a <unknown>
#1 0x561d670fb460 <unknown>
#2 0x561d67147f96 <unknown>
#3 0x561d67148221 <unknown>
#4 0x561d6718d5d4 <unknown>
#5 0x561d6716c03d <unknown>
#6 0x561d6718aaf6 <unknown>
#7 0x561d6716bdb3 <unknown>
#8 0x561d6713ac10 <unknown>
#9 0x561d6713bbee <unknown>
#10 0x561d675ac39b <unknown>
#11 0x561d675b0338 <unknown>
#12 0x561d67599ebc <unknown>
#13 0x561d675b0eb7 <unknown>
#14 0x561d6757f10f <unknown>
#15 0x561d675ce828 <unknown>
#16 0x561d675ce9f0 <unknown>
#17 0x561d675def86 <unknown>
#18 0x7fc2fe499144 <unknown>


During handling of the above exception, another exception occurred:

Traceback (most recent call last):
  File "/home/airflow/.local/lib/python3.12/site-packages/airflow/task/task_runner/standard_task_runner.py", line 117, in _start_by_fork
    ret = args.func(args, dag=self.dag)
          ^^^^^^^^^^^^^^^^^^^^^^^^^^^^^
  File "/home/airflow/.local/lib/python3.12/site-packages/airflow/cli/cli_config.py", line 49, in command
    return func(*args, **kwargs)
           ^^^^^^^^^^^^^^^^^^^^^
  File "/home/airflow/.local/lib/python3.12/site-packages/airflow/utils/cli.py", line 115, in wrapper
    return f(*args, **kwargs)
           ^^^^^^^^^^^^^^^^^^
  File "/home/airflow/.local/lib/python3.12/site-packages/airflow/cli/commands/task_command.py", line 483, in task_run
    task_return_code = _run_task_by_selected_method(args, _dag, ti)
                       ^^^^^^^^^^^^^^^^^^^^^^^^^^^^^^^^^^^^^^^^^^^^
  File "/home/airflow/.local/lib/python3.12/site-packages/airflow/cli/commands/task_command.py", line 256, in _run_task_by_selected_method
    return _run_raw_task(args, ti)
           ^^^^^^^^^^^^^^^^^^^^^^^
  File "/home/airflow/.local/lib/python3.12/site-packages/airflow/cli/commands/task_command.py", line 341, in _run_raw_task
    return ti._run_raw_task(
           ^^^^^^^^^^^^^^^^^
  File "/home/airflow/.local/lib/python3.12/site-packages/airflow/utils/session.py", line 97, in wrapper
    return func(*args, session=session, **kwargs)
           ^^^^^^^^^^^^^^^^^^^^^^^^^^^^^^^^^^^^^^
  File "/home/airflow/.local/lib/python3.12/site-packages/airflow/models/taskinstance.py", line 3004, in _run_raw_task
    return _run_raw_task(
           ^^^^^^^^^^^^^^
  File "/home/airflow/.local/lib/python3.12/site-packages/airflow/models/taskinstance.py", line 273, in _run_raw_task
    TaskInstance._execute_task_with_callbacks(
  File "/home/airflow/.local/lib/python3.12/site-packages/airflow/models/taskinstance.py", line 3158, in _execute_task_with_callbacks
    result = self._execute_task(context, task_orig)
             ^^^^^^^^^^^^^^^^^^^^^^^^^^^^^^^^^^^^^^
  File "/home/airflow/.local/lib/python3.12/site-packages/airflow/models/taskinstance.py", line 3182, in _execute_task
    return _execute_task(self, context, task_orig)
           ^^^^^^^^^^^^^^^^^^^^^^^^^^^^^^^^^^^^^^^
  File "/home/airflow/.local/lib/python3.12/site-packages/airflow/models/taskinstance.py", line 767, in _execute_task
    result = _execute_callable(context=context, **execute_callable_kwargs)
             ^^^^^^^^^^^^^^^^^^^^^^^^^^^^^^^^^^^^^^^^^^^^^^^^^^^^^^^^^^^^^
  File "/home/airflow/.local/lib/python3.12/site-packages/airflow/models/taskinstance.py", line 733, in _execute_callable
    return ExecutionCallableRunner(
           ^^^^^^^^^^^^^^^^^^^^^^^^
  File "/home/airflow/.local/lib/python3.12/site-packages/airflow/utils/operator_helpers.py", line 252, in run
    return self.func(*args, **kwargs)
           ^^^^^^^^^^^^^^^^^^^^^^^^^^
  File "/home/airflow/.local/lib/python3.12/site-packages/airflow/models/baseoperator.py", line 406, in wrapper
    return func(self, *args, **kwargs)
           ^^^^^^^^^^^^^^^^^^^^^^^^^^^
  File "/home/airflow/.local/lib/python3.12/site-packages/airflow/operators/python.py", line 238, in execute
    return_value = self.execute_callable()
                   ^^^^^^^^^^^^^^^^^^^^^^^
  File "/home/airflow/.local/lib/python3.12/site-packages/airflow/operators/python.py", line 256, in execute_callable
    return runner.run(*self.op_args, **self.op_kwargs)
           ^^^^^^^^^^^^^^^^^^^^^^^^^^^^^^^^^^^^^^^^^^^
  File "/home/airflow/.local/lib/python3.12/site-packages/airflow/utils/operator_helpers.py", line 252, in run
    return self.func(*args, **kwargs)
           ^^^^^^^^^^^^^^^^^^^^^^^^^^
  File "/opt/airflow/dags/dcard_dag.py", line 222, in crawl_dcard
    driver1.quit()
    ^^^^^^^
UnboundLocalError: cannot access local variable 'driver1' where it is not associated with a value
[2024-10-23T07:15:40.989+0000] {local_task_job_runner.py:266} INFO - Task exited with return code 1
[2024-10-23T07:15:41.022+0000] {taskinstance.py:3900} INFO - 0 downstream tasks scheduled from follow-on schedule check
[2024-10-23T07:15:41.024+0000] {local_task_job_runner.py:245} INFO - ::endgroup::
