[2024-10-23T07:04:26.498+0000] {local_task_job_runner.py:123} INFO - ::group::Pre task execution logs
[2024-10-23T07:04:26.514+0000] {taskinstance.py:2612} INFO - Dependencies all met for dep_context=non-requeueable deps ti=<TaskInstance: dcard_dag.run_crawl_task manual__2024-10-23T07:04:18.466610+00:00 [queued]>
[2024-10-23T07:04:26.524+0000] {taskinstance.py:2612} INFO - Dependencies all met for dep_context=requeueable deps ti=<TaskInstance: dcard_dag.run_crawl_task manual__2024-10-23T07:04:18.466610+00:00 [queued]>
[2024-10-23T07:04:26.524+0000] {taskinstance.py:2865} INFO - Starting attempt 1 of 2
[2024-10-23T07:04:26.548+0000] {taskinstance.py:2888} INFO - Executing <Task(PythonOperator): run_crawl_task> on 2024-10-23 07:04:18.466610+00:00
[2024-10-23T07:04:26.555+0000] {standard_task_runner.py:72} INFO - Started process 20108 to run task
[2024-10-23T07:04:26.569+0000] {standard_task_runner.py:104} INFO - Running: ['airflow', 'tasks', 'run', 'dcard_dag', 'run_crawl_task', 'manual__2024-10-23T07:04:18.466610+00:00', '--job-id', '855', '--raw', '--subdir', 'DAGS_FOLDER/dcard_dag.py', '--cfg-path', '/tmp/tmp_d8tzdyr']
[2024-10-23T07:04:26.574+0000] {standard_task_runner.py:105} INFO - Job 855: Subtask run_crawl_task
[2024-10-23T07:04:26.670+0000] {task_command.py:467} INFO - Running <TaskInstance: dcard_dag.run_crawl_task manual__2024-10-23T07:04:18.466610+00:00 [running]> on host 60bbe790d101
[2024-10-23T07:04:26.789+0000] {taskinstance.py:3131} INFO - Exporting env vars: AIRFLOW_CTX_DAG_OWNER='airflow' AIRFLOW_CTX_DAG_ID='dcard_dag' AIRFLOW_CTX_TASK_ID='run_crawl_task' AIRFLOW_CTX_EXECUTION_DATE='2024-10-23T07:04:18.466610+00:00' AIRFLOW_CTX_TRY_NUMBER='1' AIRFLOW_CTX_DAG_RUN_ID='manual__2024-10-23T07:04:18.466610+00:00'
[2024-10-23T07:04:26.791+0000] {taskinstance.py:731} INFO - ::endgroup::
[2024-10-23T07:04:29.238+0000] {patcher.py:346} INFO - patching driver executable /home/airflow/.local/share/undetected_chromedriver/undetected_chromedriver
[2024-10-23T07:05:29.456+0000] {taskinstance.py:3310} ERROR - Task failed with exception
Traceback (most recent call last):
  File "/home/airflow/.local/lib/python3.12/site-packages/airflow/models/taskinstance.py", line 767, in _execute_task
    result = _execute_callable(context=context, **execute_callable_kwargs)
             ^^^^^^^^^^^^^^^^^^^^^^^^^^^^^^^^^^^^^^^^^^^^^^^^^^^^^^^^^^^^^
  File "/home/airflow/.local/lib/python3.12/site-packages/airflow/models/taskinstance.py", line 733, in _execute_callable
    return ExecutionCallableRunner(
           ^^^^^^^^^^^^^^^^^^^^^^^^
  File "/home/airflow/.local/lib/python3.12/site-packages/airflow/utils/operator_helpers.py", line 252, in run
    return self.func(*args, **kwargs)
           ^^^^^^^^^^^^^^^^^^^^^^^^^^
  File "/home/airflow/.local/lib/python3.12/site-packages/airflow/models/baseoperator.py", line 406, in wrapper
    return func(self, *args, **kwargs)
           ^^^^^^^^^^^^^^^^^^^^^^^^^^^
  File "/home/airflow/.local/lib/python3.12/site-packages/airflow/operators/python.py", line 238, in execute
    return_value = self.execute_callable()
                   ^^^^^^^^^^^^^^^^^^^^^^^
  File "/home/airflow/.local/lib/python3.12/site-packages/airflow/operators/python.py", line 256, in execute_callable
    return runner.run(*self.op_args, **self.op_kwargs)
           ^^^^^^^^^^^^^^^^^^^^^^^^^^^^^^^^^^^^^^^^^^^
  File "/home/airflow/.local/lib/python3.12/site-packages/airflow/utils/operator_helpers.py", line 252, in run
    return self.func(*args, **kwargs)
           ^^^^^^^^^^^^^^^^^^^^^^^^^^
  File "/opt/airflow/dags/dcard_dag.py", line 33, in crawl_dcard
    driver = uc.Chrome()
             ^^^^^^^^^^^
  File "/home/airflow/.local/lib/python3.12/site-packages/undetected_chromedriver/__init__.py", line 466, in __init__
    super(Chrome, self).__init__(
  File "/home/airflow/.local/lib/python3.12/site-packages/selenium/webdriver/chrome/webdriver.py", line 45, in __init__
    super().__init__(
  File "/home/airflow/.local/lib/python3.12/site-packages/selenium/webdriver/chromium/webdriver.py", line 66, in __init__
    super().__init__(command_executor=executor, options=options)
  File "/home/airflow/.local/lib/python3.12/site-packages/selenium/webdriver/remote/webdriver.py", line 212, in __init__
    self.start_session(capabilities)
  File "/home/airflow/.local/lib/python3.12/site-packages/undetected_chromedriver/__init__.py", line 724, in start_session
    super(selenium.webdriver.chrome.webdriver.WebDriver, self).start_session(
  File "/home/airflow/.local/lib/python3.12/site-packages/selenium/webdriver/remote/webdriver.py", line 299, in start_session
    response = self.execute(Command.NEW_SESSION, caps)["value"]
               ^^^^^^^^^^^^^^^^^^^^^^^^^^^^^^^^^^^^^^^
  File "/home/airflow/.local/lib/python3.12/site-packages/selenium/webdriver/remote/webdriver.py", line 354, in execute
    self.error_handler.check_response(response)
  File "/home/airflow/.local/lib/python3.12/site-packages/selenium/webdriver/remote/errorhandler.py", line 229, in check_response
    raise exception_class(message, screen, stacktrace)
selenium.common.exceptions.SessionNotCreatedException: Message: session not created: cannot connect to chrome at 127.0.0.1:60071
from chrome not reachable
Stacktrace:
#0 0x56176783310a <unknown>
#1 0x56176734e2bd <unknown>
#2 0x56176733a4bf <unknown>
#3 0x56176738956c <unknown>
#4 0x56176737f392 <unknown>
#5 0x5617673cb156 <unknown>
#6 0x5617673ca7a6 <unknown>
#7 0x5617673bedb3 <unknown>
#8 0x56176738dc10 <unknown>
#9 0x56176738ebee <unknown>
#10 0x5617677ff39b <unknown>
#11 0x561767803338 <unknown>
#12 0x5617677ecebc <unknown>
#13 0x561767803eb7 <unknown>
#14 0x5617677d210f <unknown>
#15 0x561767821828 <unknown>
#16 0x5617678219f0 <unknown>
#17 0x561767831f86 <unknown>
#18 0x7f1d61001144 <unknown>

[2024-10-23T07:05:29.480+0000] {taskinstance.py:1225} INFO - Marking task as UP_FOR_RETRY. dag_id=dcard_dag, task_id=run_crawl_task, run_id=manual__2024-10-23T07:04:18.466610+00:00, execution_date=20241023T070418, start_date=20241023T070426, end_date=20241023T070529
[2024-10-23T07:05:29.501+0000] {taskinstance.py:340} INFO - ::group::Post task execution logs
[2024-10-23T07:05:29.501+0000] {standard_task_runner.py:124} ERROR - Failed to execute job 855 for task run_crawl_task (Message: session not created: cannot connect to chrome at 127.0.0.1:60071
from chrome not reachable
Stacktrace:
#0 0x56176783310a <unknown>
#1 0x56176734e2bd <unknown>
#2 0x56176733a4bf <unknown>
#3 0x56176738956c <unknown>
#4 0x56176737f392 <unknown>
#5 0x5617673cb156 <unknown>
#6 0x5617673ca7a6 <unknown>
#7 0x5617673bedb3 <unknown>
#8 0x56176738dc10 <unknown>
#9 0x56176738ebee <unknown>
#10 0x5617677ff39b <unknown>
#11 0x561767803338 <unknown>
#12 0x5617677ecebc <unknown>
#13 0x561767803eb7 <unknown>
#14 0x5617677d210f <unknown>
#15 0x561767821828 <unknown>
#16 0x5617678219f0 <unknown>
#17 0x561767831f86 <unknown>
#18 0x7f1d61001144 <unknown>
; 20108)
Traceback (most recent call last):
  File "/home/airflow/.local/lib/python3.12/site-packages/airflow/task/task_runner/standard_task_runner.py", line 117, in _start_by_fork
    ret = args.func(args, dag=self.dag)
          ^^^^^^^^^^^^^^^^^^^^^^^^^^^^^
  File "/home/airflow/.local/lib/python3.12/site-packages/airflow/cli/cli_config.py", line 49, in command
    return func(*args, **kwargs)
           ^^^^^^^^^^^^^^^^^^^^^
  File "/home/airflow/.local/lib/python3.12/site-packages/airflow/utils/cli.py", line 115, in wrapper
    return f(*args, **kwargs)
           ^^^^^^^^^^^^^^^^^^
  File "/home/airflow/.local/lib/python3.12/site-packages/airflow/cli/commands/task_command.py", line 483, in task_run
    task_return_code = _run_task_by_selected_method(args, _dag, ti)
                       ^^^^^^^^^^^^^^^^^^^^^^^^^^^^^^^^^^^^^^^^^^^^
  File "/home/airflow/.local/lib/python3.12/site-packages/airflow/cli/commands/task_command.py", line 256, in _run_task_by_selected_method
    return _run_raw_task(args, ti)
           ^^^^^^^^^^^^^^^^^^^^^^^
  File "/home/airflow/.local/lib/python3.12/site-packages/airflow/cli/commands/task_command.py", line 341, in _run_raw_task
    return ti._run_raw_task(
           ^^^^^^^^^^^^^^^^^
  File "/home/airflow/.local/lib/python3.12/site-packages/airflow/utils/session.py", line 97, in wrapper
    return func(*args, session=session, **kwargs)
           ^^^^^^^^^^^^^^^^^^^^^^^^^^^^^^^^^^^^^^
  File "/home/airflow/.local/lib/python3.12/site-packages/airflow/models/taskinstance.py", line 3004, in _run_raw_task
    return _run_raw_task(
           ^^^^^^^^^^^^^^
  File "/home/airflow/.local/lib/python3.12/site-packages/airflow/models/taskinstance.py", line 273, in _run_raw_task
    TaskInstance._execute_task_with_callbacks(
  File "/home/airflow/.local/lib/python3.12/site-packages/airflow/models/taskinstance.py", line 3158, in _execute_task_with_callbacks
    result = self._execute_task(context, task_orig)
             ^^^^^^^^^^^^^^^^^^^^^^^^^^^^^^^^^^^^^^
  File "/home/airflow/.local/lib/python3.12/site-packages/airflow/models/taskinstance.py", line 3182, in _execute_task
    return _execute_task(self, context, task_orig)
           ^^^^^^^^^^^^^^^^^^^^^^^^^^^^^^^^^^^^^^^
  File "/home/airflow/.local/lib/python3.12/site-packages/airflow/models/taskinstance.py", line 767, in _execute_task
    result = _execute_callable(context=context, **execute_callable_kwargs)
             ^^^^^^^^^^^^^^^^^^^^^^^^^^^^^^^^^^^^^^^^^^^^^^^^^^^^^^^^^^^^^
  File "/home/airflow/.local/lib/python3.12/site-packages/airflow/models/taskinstance.py", line 733, in _execute_callable
    return ExecutionCallableRunner(
           ^^^^^^^^^^^^^^^^^^^^^^^^
  File "/home/airflow/.local/lib/python3.12/site-packages/airflow/utils/operator_helpers.py", line 252, in run
    return self.func(*args, **kwargs)
           ^^^^^^^^^^^^^^^^^^^^^^^^^^
  File "/home/airflow/.local/lib/python3.12/site-packages/airflow/models/baseoperator.py", line 406, in wrapper
    return func(self, *args, **kwargs)
           ^^^^^^^^^^^^^^^^^^^^^^^^^^^
  File "/home/airflow/.local/lib/python3.12/site-packages/airflow/operators/python.py", line 238, in execute
    return_value = self.execute_callable()
                   ^^^^^^^^^^^^^^^^^^^^^^^
  File "/home/airflow/.local/lib/python3.12/site-packages/airflow/operators/python.py", line 256, in execute_callable
    return runner.run(*self.op_args, **self.op_kwargs)
           ^^^^^^^^^^^^^^^^^^^^^^^^^^^^^^^^^^^^^^^^^^^
  File "/home/airflow/.local/lib/python3.12/site-packages/airflow/utils/operator_helpers.py", line 252, in run
    return self.func(*args, **kwargs)
           ^^^^^^^^^^^^^^^^^^^^^^^^^^
  File "/opt/airflow/dags/dcard_dag.py", line 33, in crawl_dcard
    driver = uc.Chrome()
             ^^^^^^^^^^^
  File "/home/airflow/.local/lib/python3.12/site-packages/undetected_chromedriver/__init__.py", line 466, in __init__
    super(Chrome, self).__init__(
  File "/home/airflow/.local/lib/python3.12/site-packages/selenium/webdriver/chrome/webdriver.py", line 45, in __init__
    super().__init__(
  File "/home/airflow/.local/lib/python3.12/site-packages/selenium/webdriver/chromium/webdriver.py", line 66, in __init__
    super().__init__(command_executor=executor, options=options)
  File "/home/airflow/.local/lib/python3.12/site-packages/selenium/webdriver/remote/webdriver.py", line 212, in __init__
    self.start_session(capabilities)
  File "/home/airflow/.local/lib/python3.12/site-packages/undetected_chromedriver/__init__.py", line 724, in start_session
    super(selenium.webdriver.chrome.webdriver.WebDriver, self).start_session(
  File "/home/airflow/.local/lib/python3.12/site-packages/selenium/webdriver/remote/webdriver.py", line 299, in start_session
    response = self.execute(Command.NEW_SESSION, caps)["value"]
               ^^^^^^^^^^^^^^^^^^^^^^^^^^^^^^^^^^^^^^^
  File "/home/airflow/.local/lib/python3.12/site-packages/selenium/webdriver/remote/webdriver.py", line 354, in execute
    self.error_handler.check_response(response)
  File "/home/airflow/.local/lib/python3.12/site-packages/selenium/webdriver/remote/errorhandler.py", line 229, in check_response
    raise exception_class(message, screen, stacktrace)
selenium.common.exceptions.SessionNotCreatedException: Message: session not created: cannot connect to chrome at 127.0.0.1:60071
from chrome not reachable
Stacktrace:
#0 0x56176783310a <unknown>
#1 0x56176734e2bd <unknown>
#2 0x56176733a4bf <unknown>
#3 0x56176738956c <unknown>
#4 0x56176737f392 <unknown>
#5 0x5617673cb156 <unknown>
#6 0x5617673ca7a6 <unknown>
#7 0x5617673bedb3 <unknown>
#8 0x56176738dc10 <unknown>
#9 0x56176738ebee <unknown>
#10 0x5617677ff39b <unknown>
#11 0x561767803338 <unknown>
#12 0x5617677ecebc <unknown>
#13 0x561767803eb7 <unknown>
#14 0x5617677d210f <unknown>
#15 0x561767821828 <unknown>
#16 0x5617678219f0 <unknown>
#17 0x561767831f86 <unknown>
#18 0x7f1d61001144 <unknown>

[2024-10-23T07:05:29.543+0000] {local_task_job_runner.py:266} INFO - Task exited with return code 1
[2024-10-23T07:05:29.609+0000] {taskinstance.py:3900} INFO - 0 downstream tasks scheduled from follow-on schedule check
[2024-10-23T07:05:29.610+0000] {local_task_job_runner.py:245} INFO - ::endgroup::
